[2025-06-17T04:14:23.842+0300] {taskinstance.py:1157} INFO - Dependencies all met for dep_context=non-requeueable deps ti=<TaskInstance: breast_cancer_ml_pipeline.load_data scheduled__2025-06-15T00:00:00+00:00 [queued]>
[2025-06-17T04:14:23.859+0300] {taskinstance.py:1157} INFO - Dependencies all met for dep_context=requeueable deps ti=<TaskInstance: breast_cancer_ml_pipeline.load_data scheduled__2025-06-15T00:00:00+00:00 [queued]>
[2025-06-17T04:14:23.860+0300] {taskinstance.py:1359} INFO - Starting attempt 10 of 13
[2025-06-17T04:14:23.903+0300] {taskinstance.py:1380} INFO - Executing <Task(PythonOperator): load_data> on 2025-06-15 00:00:00+00:00
[2025-06-17T04:14:23.915+0300] {standard_task_runner.py:57} INFO - Started process 19129 to run task
[2025-06-17T04:14:23.928+0300] {standard_task_runner.py:84} INFO - Running: ['airflow', 'tasks', 'run', 'breast_cancer_ml_pipeline', 'load_data', 'scheduled__2025-06-15T00:00:00+00:00', '--job-id', '59', '--raw', '--subdir', 'DAGS_FOLDER/main.py', '--cfg-path', '/tmp/tmpxqlqyt8p']
[2025-06-17T04:14:23.932+0300] {standard_task_runner.py:85} INFO - Job 59: Subtask load_data
[2025-06-17T04:14:24.051+0300] {task_command.py:415} INFO - Running <TaskInstance: breast_cancer_ml_pipeline.load_data scheduled__2025-06-15T00:00:00+00:00 [running]> on host ubuntu.myguest.virtualbox.org
[2025-06-17T04:14:24.167+0300] {taskinstance.py:1660} INFO - Exporting env vars: AIRFLOW_CTX_DAG_OWNER='airflow' AIRFLOW_CTX_DAG_ID='breast_cancer_ml_pipeline' AIRFLOW_CTX_TASK_ID='load_data' AIRFLOW_CTX_EXECUTION_DATE='2025-06-15T00:00:00+00:00' AIRFLOW_CTX_TRY_NUMBER='10' AIRFLOW_CTX_DAG_RUN_ID='scheduled__2025-06-15T00:00:00+00:00'
[2025-06-17T04:14:24.171+0300] {taskinstance.py:1935} ERROR - Task failed with exception
Traceback (most recent call last):
  File "/home/qwerty/.local/lib/python3.10/site-packages/airflow/operators/python.py", line 192, in execute
    return_value = self.execute_callable()
  File "/home/qwerty/.local/lib/python3.10/site-packages/airflow/operators/python.py", line 209, in execute_callable
    return self.python_callable(*self.op_args, **self.op_kwargs)
  File "/home/qwerty/DE_project/airflow/dags/main.py", line 35, in load_data_task
    from etl.Load import load_data
ModuleNotFoundError: No module named 'etl'
[2025-06-17T04:14:24.182+0300] {taskinstance.py:1398} INFO - Marking task as UP_FOR_RETRY. dag_id=breast_cancer_ml_pipeline, task_id=load_data, execution_date=20250615T000000, start_date=20250617T011423, end_date=20250617T011424
[2025-06-17T04:14:24.207+0300] {standard_task_runner.py:104} ERROR - Failed to execute job 59 for task load_data (No module named 'etl'; 19129)
[2025-06-17T04:14:24.226+0300] {local_task_job_runner.py:228} INFO - Task exited with return code 1
[2025-06-17T04:14:24.286+0300] {taskinstance.py:2776} INFO - 0 downstream tasks scheduled from follow-on schedule check
