[2025-06-17T04:11:46.884+0300] {taskinstance.py:1157} INFO - Dependencies all met for dep_context=non-requeueable deps ti=<TaskInstance: breast_cancer_ml_pipeline.load_data scheduled__2025-06-15T00:00:00+00:00 [queued]>
[2025-06-17T04:11:46.899+0300] {taskinstance.py:1157} INFO - Dependencies all met for dep_context=requeueable deps ti=<TaskInstance: breast_cancer_ml_pipeline.load_data scheduled__2025-06-15T00:00:00+00:00 [queued]>
[2025-06-17T04:11:46.899+0300] {taskinstance.py:1359} INFO - Starting attempt 9 of 12
[2025-06-17T04:11:46.933+0300] {taskinstance.py:1380} INFO - Executing <Task(PythonOperator): load_data> on 2025-06-15 00:00:00+00:00
[2025-06-17T04:11:46.943+0300] {standard_task_runner.py:57} INFO - Started process 18948 to run task
[2025-06-17T04:11:46.953+0300] {standard_task_runner.py:84} INFO - Running: ['airflow', 'tasks', 'run', 'breast_cancer_ml_pipeline', 'load_data', 'scheduled__2025-06-15T00:00:00+00:00', '--job-id', '58', '--raw', '--subdir', 'DAGS_FOLDER/main.py', '--cfg-path', '/tmp/tmp2vt9h81p']
[2025-06-17T04:11:46.956+0300] {standard_task_runner.py:85} INFO - Job 58: Subtask load_data
[2025-06-17T04:11:47.080+0300] {task_command.py:415} INFO - Running <TaskInstance: breast_cancer_ml_pipeline.load_data scheduled__2025-06-15T00:00:00+00:00 [running]> on host ubuntu.myguest.virtualbox.org
[2025-06-17T04:11:47.202+0300] {taskinstance.py:1660} INFO - Exporting env vars: AIRFLOW_CTX_DAG_OWNER='airflow' AIRFLOW_CTX_DAG_ID='breast_cancer_ml_pipeline' AIRFLOW_CTX_TASK_ID='load_data' AIRFLOW_CTX_EXECUTION_DATE='2025-06-15T00:00:00+00:00' AIRFLOW_CTX_TRY_NUMBER='9' AIRFLOW_CTX_DAG_RUN_ID='scheduled__2025-06-15T00:00:00+00:00'
[2025-06-17T04:11:47.207+0300] {taskinstance.py:1935} ERROR - Task failed with exception
Traceback (most recent call last):
  File "/home/qwerty/.local/lib/python3.10/site-packages/airflow/operators/python.py", line 192, in execute
    return_value = self.execute_callable()
  File "/home/qwerty/.local/lib/python3.10/site-packages/airflow/operators/python.py", line 209, in execute_callable
    return self.python_callable(*self.op_args, **self.op_kwargs)
  File "/home/qwerty/DE_project/airflow/dags/main.py", line 32, in load_data_task
    from etl.Load import load_data
ModuleNotFoundError: No module named 'etl'
[2025-06-17T04:11:47.216+0300] {taskinstance.py:1398} INFO - Marking task as UP_FOR_RETRY. dag_id=breast_cancer_ml_pipeline, task_id=load_data, execution_date=20250615T000000, start_date=20250617T011146, end_date=20250617T011147
[2025-06-17T04:11:47.237+0300] {standard_task_runner.py:104} ERROR - Failed to execute job 58 for task load_data (No module named 'etl'; 18948)
[2025-06-17T04:11:47.254+0300] {local_task_job_runner.py:228} INFO - Task exited with return code 1
[2025-06-17T04:11:47.291+0300] {taskinstance.py:2776} INFO - 0 downstream tasks scheduled from follow-on schedule check
