[2025-06-17T04:07:49.881+0300] {taskinstance.py:1157} INFO - Dependencies all met for dep_context=non-requeueable deps ti=<TaskInstance: breast_cancer_ml_pipeline.load_data scheduled__2025-06-15T00:00:00+00:00 [queued]>
[2025-06-17T04:07:49.889+0300] {taskinstance.py:1157} INFO - Dependencies all met for dep_context=requeueable deps ti=<TaskInstance: breast_cancer_ml_pipeline.load_data scheduled__2025-06-15T00:00:00+00:00 [queued]>
[2025-06-17T04:07:49.890+0300] {taskinstance.py:1359} INFO - Starting attempt 8 of 11
[2025-06-17T04:07:49.916+0300] {taskinstance.py:1380} INFO - Executing <Task(PythonOperator): load_data> on 2025-06-15 00:00:00+00:00
[2025-06-17T04:07:49.924+0300] {standard_task_runner.py:57} INFO - Started process 18699 to run task
[2025-06-17T04:07:49.931+0300] {standard_task_runner.py:84} INFO - Running: ['airflow', 'tasks', 'run', 'breast_cancer_ml_pipeline', 'load_data', 'scheduled__2025-06-15T00:00:00+00:00', '--job-id', '57', '--raw', '--subdir', 'DAGS_FOLDER/main.py', '--cfg-path', '/tmp/tmpl3u406ur']
[2025-06-17T04:07:49.933+0300] {standard_task_runner.py:85} INFO - Job 57: Subtask load_data
[2025-06-17T04:07:50.023+0300] {task_command.py:415} INFO - Running <TaskInstance: breast_cancer_ml_pipeline.load_data scheduled__2025-06-15T00:00:00+00:00 [running]> on host ubuntu.myguest.virtualbox.org
[2025-06-17T04:07:50.128+0300] {taskinstance.py:1660} INFO - Exporting env vars: AIRFLOW_CTX_DAG_OWNER='airflow' AIRFLOW_CTX_DAG_ID='breast_cancer_ml_pipeline' AIRFLOW_CTX_TASK_ID='load_data' AIRFLOW_CTX_EXECUTION_DATE='2025-06-15T00:00:00+00:00' AIRFLOW_CTX_TRY_NUMBER='8' AIRFLOW_CTX_DAG_RUN_ID='scheduled__2025-06-15T00:00:00+00:00'
[2025-06-17T04:07:50.133+0300] {taskinstance.py:1935} ERROR - Task failed with exception
Traceback (most recent call last):
  File "/home/qwerty/.local/lib/python3.10/site-packages/airflow/operators/python.py", line 192, in execute
    return_value = self.execute_callable()
  File "/home/qwerty/.local/lib/python3.10/site-packages/airflow/operators/python.py", line 209, in execute_callable
    return self.python_callable(*self.op_args, **self.op_kwargs)
  File "/home/qwerty/DE_project/airflow/dags/main.py", line 29, in load_data_task
    from etl.Load import load_data
ModuleNotFoundError: No module named 'etl'
[2025-06-17T04:07:50.141+0300] {taskinstance.py:1398} INFO - Marking task as UP_FOR_RETRY. dag_id=breast_cancer_ml_pipeline, task_id=load_data, execution_date=20250615T000000, start_date=20250617T010749, end_date=20250617T010750
[2025-06-17T04:07:50.161+0300] {standard_task_runner.py:104} ERROR - Failed to execute job 57 for task load_data (No module named 'etl'; 18699)
[2025-06-17T04:07:50.185+0300] {local_task_job_runner.py:228} INFO - Task exited with return code 1
[2025-06-17T04:07:50.221+0300] {taskinstance.py:2776} INFO - 0 downstream tasks scheduled from follow-on schedule check
